Workbook

Sheet Ficha de datos
A1: Valor de Inversión | B1: % | C1: ROI | D1: % | E1: Facilidad de Implementación | F1: % | G1: Impacto | H1: % MIN-MAX
A2: <=10,000,000$ | B2: 1 | C2: <3 MESES | D2: 1 | E2: A (Facil) | F2: 1 | G2: Ambiental | H2: 0-25%
A3: >10,000,000$ <=20,000,000$ | B3: 0.6 | C3: >3 MESES<6 MESES | D3: 0.75 | E3: B (Intermedio) | F3: 0.5 | G3: Económico | H3: 0-25%
A4: >20,000,000$ | B4: 0.2 | C4: > 6 MESES | D4: 0.25 | E4: C (Dificil) | F4: 0.2 | G4: SST | H4: 0-20%
G5: Productividad | H5: 0-25%
A6: Máximo por idea | B6: 22000 | G6: Orden y aseo | H6: 0-5%
B8: 0.1 | D8: 0.1 | F8: 0.1 | H8: 0.7
A9: 1 | B9: =$B$6*B8*B2 -> 2200 | C9: 1 | D9: =$B$6*D8*D2 -> 2200 | E9: 1 | F9: =$B$6*F8*F2 -> 2200 | G9: 0 | H9: =+$H$15*G9 -> 0 | I9: Ambiental
A10: 0.6 | B10: =B6*0.1*B3 -> 1320 | C10: 0.75 | D10: =C10*D9 -> 1650 | E10: 0.5 | F10: =F9*E10 -> 1100 | G10: 0.25 | H10: =+$H$15*G10 -> 3850 | I10: Económico
A11: 0.2 | B11: =$B$6*0.1*B4 -> 440 | C11: 0.25 | D11: =D9*C11 -> 550 | E11: 0.2 | F11: =F9*E11 -> 440 | G11: 0 | H11: =+$H$15*G11 -> 0 | I11: SST
G12: 0.25 | H12: =+$H$15*G12 -> 3850 | I12: Productividad
G13: 0 | H13: =+$H$15*G13 -> 0 | I13: Orden y aseo
H15: =B6*H8 -> 15400

Sheet Tabla Calif. Puntos
C1: CALIFICACIÓN PLAN DE PUNTOS | Y1: CÓDIGO: FO-SDG-28 VERSIÓN: 01 FECHA: 19/07/2024
A3: FASE 1 CALIFICACIÓN | N3: 0.1 | O3: 0.1 | P3: 0.1 | Q3: 0.7 | R3: 1 | T3: FASE 2 IMPLEMENTACIÓN
A4: DOCUMENTO | B4: NOMBRE | C4: RADICADO | D4: PROCESO | E4: ESTADO | F4: VALOR INVERSIÓN | G4: ROI (MESES) | H4: FACILIDAD IMPLEM. | I4: IMPACTO AMBIENTAL (Máx. 25%) | J4: IMPACTO ECONÓMICO (Máx. 25%) | K4: IMPACTO SST (Máx. 20%) | L4: IMPACTO PRODUCTIVIDAD (Máx. 25%) | M4: IMPACTO ORDEN Y ASEO (Máx. 5%) | N4: PUNTOS VALOR INVERSIÓN | O4: PUNTOS ROI | P4: PUNTOS FACILIDAD IMPLEM. | Q4: PUNTOS IMPACTO | R4: PUNTOS TOTALES | S4: OBSERVACIONES | T4: CLASIFICACIÓN | U4: PRIORIDAD | V4: RESUMEN IDEA | W4: OBSERVACIONES | X4: RESPONSABLE | Y4: ESTADO IMPLEMENTACIÓN
A5: 1001812262 | B5: José Julián Betancur Estrada | C5: 501 | D5: Producción | E5: Descartada | N5: =IF(Tabla5[[#This Row],[VALOR INVERSIÓN]]="","",IF(Tabla5[[#This Row],[VALOR INVERSIÓN]]<=10000000,100%*10%*22000,IF(AND(Tabla5[[#This Row],[VALOR INVERSIÓN]]>10000000,Tabla5[[#This Row],[VALOR INVERSIÓN]]<=20000000),60%*10%*22000,20%*10%*22000))) | O5: =IF(Tabla5[[#This Row],[ROI (MESES)]]="","",IF(Tabla5[[#This Row],[ROI (MESES)]]="N/A","0",IF(Tabla5[[#This Row],[ROI (MESES)]]="<=3",100%*10%*22000,IF(Tabla5[[#This Row],[ROI (MESES)]]=">3<=6",75%*10%*22000,25%*10%*22000)))) | P5: =IF(Tabla5[[#This Row],[FACILIDAD IMPLEM.]]="","",IF(Tabla5[[#This Row],[FACILIDAD IMPLEM.]]="A",100%*10%*22000,IF(AND(Tabla5[[#This Row],[FACILIDAD IMPLEM.]]="B"),50%*10%*22000,20%*10%*22000))) | Q5: =Tabla5[[#This Row],[IMPACTO AMBIENTAL (Máx. 25%)]]*70%*22000+Tabla5[[#This Row],[IMPACTO ECONÓMICO (Máx. 25%)]]*70%*22000+Tabla5[[#This Row],[IMPACTO SST (Máx. 20%)]]*70%*22000+Tabla5[[#This Row],[IMPACTO PRODUCTIVIDAD (Máx. 25%)]]*70%*22000+Tabla5[[#This Row],[IMPACTO ORDEN Y ASEO (Máx. 5%)]]*70%*22000 -> 0 | R5: =IFERROR(Tabla5[[#This Row],[PUNTOS VALOR INVERSIÓN]]+Tabla5[[#This Row],[PUNTOS ROI ]]+Tabla5[[#This Row],[PUNTOS FACILIDAD IMPLEM. ]]+Tabla5[[#This Row],[PUNTOS IMPACTO ]],"")
A6: 59834499 | B6: Victoria Arciniegas Arteaga | C6: 502 | D6: G.Administrativa | E6: Descartada | N6: =IF(Tabla5[[#This Row],[VALOR INVERSIÓN]]="","",IF(Tabla5[[#This Row],[VALOR INVERSIÓN]]<=10000000,100%*10%*22000,IF(AND(Tabla5[[#This Row],[VALOR INVERSIÓN]]>10000000,Tabla5[[#This Row],[VALOR INVERSIÓN]]<=20000000),60%*10%*22000,20%*10%*22000))) | O6: =IF(Tabla5[[#This Row],[ROI (MESES)]]="","",IF(Tabla5[[#This Row],[ROI (MESES)]]="N/A","0",IF(Tabla5[[#This Row],[ROI (MESES)]]="<=3",100%*10%*22000,IF(Tabla5[[#This Row],[ROI (MESES)]]=">3<=6",75%*10%*22000,25%*10%*22000)))) | P6: =IF(Tabla5[[#This Row],[FACILIDAD IMPLEM.]]="","",IF(Tabla5[[#This Row],[FACILIDAD IMPLEM.]]="A",100%*10%*22000,IF(AND(Tabla5[[#This Row],[FACILIDAD IMPLEM.]]="B"),50%*10%*22000,20%*10%*22000))) | Q6: =Tabla5[[#This Row],[IMPACTO AMBIENTAL (Máx. 25%)]]*70%*22000+Tabla5[[#This Row],[IMPACTO ECONÓMICO (Máx. 25%)]]*70%*22000+Tabla5[[#This Row],[IMPACTO SST (Máx. 20%)]]*70%*22000+Tabla5[[#This Row],[IMPACTO PRODUCTIVIDAD (Máx. 25%)]]*70%*22000+Tabla5[[#This Row],[IMPACTO ORDEN Y ASEO (Máx. 5%)]]*70%*22000 -> 0 | R6: =IFERROR(Tabla5[[#This Row],[PUNTOS VALOR INVERSIÓN]]+Tabla5[[#This Row],[PUNTOS ROI ]]+Tabla5[[#This Row],[PUNTOS FACILIDAD IMPLEM. ]]+Tabla5[[#This Row],[PUNTOS IMPACTO ]],"")
A7: 1001812262 | B7: José Julián Betancur Estrada | C7: 532 | D7: Producción | E7: Descartada | N7: =IF(Tabla5[[#This Row],[VALOR INVERSIÓN]]="","",IF(Tabla5[[#This Row],[VALOR INVERSIÓN]]<=10000000,100%*10%*22000,IF(AND(Tabla5[[#This Row],[VALOR INVERSIÓN]]>10000000,Tabla5[[#This Row],[VALOR INVERSIÓN]]<=20000000),60%*10%*22000,20%*10%*22000))) | O7: =IF(Tabla5[[#This Row],[ROI (MESES)]]="","",IF(Tabla5[[#This Row],[ROI (MESES)]]="N/A","0",IF(Tabla5[[#This Row],[ROI (MESES)]]="<=3",100%*10%*22000,IF(Tabla5[[#This Row],[ROI (MESES)]]=">3<=6",75%*10%*22000,25%*10%*22000)))) | P7: =IF(Tabla5[[#This Row],[FACILIDAD IMPLEM.]]="","",IF(Tabla5[[#This Row],[FACILIDAD IMPLEM.]]="A",100%*10%*22000,IF(AND(Tabla5[[#This Row],[FACILIDAD IMPLEM.]]="B"),50%*10%*22000,20%*10%*22000))) | Q7: =Tabla5[[#This Row],[IMPACTO AMBIENTAL (Máx. 25%)]]*70%*22000+Tabla5[[#This Row],[IMPACTO ECONÓMICO (Máx. 25%)]]*70%*22000+Tabla5[[#This Row],[IMPACTO SST (Máx. 20%)]]*70%*22000+Tabla5[[#This Row],[IMPACTO PRODUCTIVIDAD (Máx. 25%)]]*70%*22000+Tabla5[[#This Row],[IMPACTO ORDEN Y ASEO (Máx. 5%)]]*70%*22000 -> 0 | R7: =IFERROR(Tabla5[[#This Row],[PUNTOS VALOR INVERSIÓN]]+Tabla5[[#This Row],[PUNTOS ROI ]]+Tabla5[[#This Row],[PUNTOS FACILIDAD IMPLEM. ]]+Tabla5[[#This Row],[PUNTOS IMPACTO ]],"")
A8: 1037572152 | B8: Jorge Andrés Carvajal | C8: 851 | D8: Producción | E8: Descartada | N8: =IF(Tabla5[[#This Row],[VALOR INVERSIÓN]]="","",IF(Tabla5[[#This Row],[VALOR INVERSIÓN]]<=10000000,100%*10%*22000,IF(AND(Tabla5[[#This Row],[VALOR INVERSIÓN]]>10000000,Tabla5[[#This Row],[VALOR INVERSIÓN]]<=20000000),60%*10%*22000,20%*10%*22000))) | O8: =IF(Tabla5[[#This Row],[ROI (MESES)]]="","",IF(Tabla5[[#This Row],[ROI (MESES)]]="N/A","0",IF(Tabla5[[#This Row],[ROI (MESES)]]="<=3",100%*10%*22000,IF(Tabla5[[#This Row],[ROI (MESES)]]=">3<=6",75%*10%*22000,25%*10%*22000)))) | P8: =IF(Tabla5[[#This Row],[FACILIDAD IMPLEM.]]="","",IF(Tabla5[[#This Row],[FACILIDAD IMPLEM.]]="A",100%*10%*22000,IF(AND(Tabla5[[#This Row],[FACILIDAD IMPLEM.]]="B"),50%*10%*22000,20%*10%*22000))) | Q8: =Tabla5[[#This Row],[IMPACTO AMBIENTAL (Máx. 25%)]]*70%*22000+Tabla5[[#This Row],[IMPACTO ECONÓMICO (Máx. 25%)]]*70%*22000+Tabla5[[#This Row],[IMPACTO SST (Máx. 20%)]]*70%*22000+Tabla5[[#This Row],[IMPACTO PRODUCTIVIDAD (Máx. 25%)]]*70%*22000+Tabla5[[#This Row],[IMPACTO ORDEN Y ASEO (Máx. 5%)]]*70%*22000 -> 0 | R8: =IFERROR(Tabla5[[#This Row],[PUNTOS VALOR INVERSIÓN]]+Tabla5[[#This Row],[PUNTOS ROI ]]+Tabla5[[#This Row],[PUNTOS FACILIDAD IMPLEM. ]]+Tabla5[[#This Row],[PUNTOS IMPACTO ]],"")
A9: 1193219755 | B9: Valentina Caruso Alian | C9: 862 | D9: SIG | E9: Descartada | N9: =IF(Tabla5[[#This Row],[VALOR INVERSIÓN]]="","",IF(Tabla5[[#This Row],[VALOR INVERSIÓN]]<=10000000,100%*10%*22000,IF(AND(Tabla5[[#This Row],[VALOR INVERSIÓN]]>10000000,Tabla5[[#This Row],[VALOR INVERSIÓN]]<=20000000),60%*10%*22000,20%*10%*22000))) | O9: =IF(Tabla5[[#This Row],[ROI (MESES)]]="","",IF(Tabla5[[#This Row],[ROI (MESES)]]="N/A","0",IF(Tabla5[[#This Row],[ROI (MESES)]]="<=3",100%*10%*22000,IF(Tabla5[[#This Row],[ROI (MESES)]]=">3<=6",75%*10%*22000,25%*10%*22000)))) | P9: =IF(Tabla5[[#This Row],[FACILIDAD IMPLEM.]]="","",IF(Tabla5[[#This Row],[FACILIDAD IMPLEM.]]="A",100%*10%*22000,IF(AND(Tabla5[[#This Row],[FACILIDAD IMPLEM.]]="B"),50%*10%*22000,20%*10%*22000))) | Q9: =Tabla5[[#This Row],[IMPACTO AMBIENTAL (Máx. 25%)]]*70%*22000+Tabla5[[#This Row],[IMPACTO ECONÓMICO (Máx. 25%)]]*70%*22000+Tabla5[[#This Row],[IMPACTO SST (Máx. 20%)]]*70%*22000+Tabla5[[#This Row],[IMPACTO PRODUCTIVIDAD (Máx. 25%)]]*70%*22000+Tabla5[[#This Row],[IMPACTO ORDEN Y ASEO (Máx. 5%)]]*70%*22000 -> 0 | R9: =IFERROR(Tabla5[[#This Row],[PUNTOS VALOR INVERSIÓN]]+Tabla5[[#This Row],[PUNTOS ROI ]]+Tabla5[[#This Row],[PUNTOS FACILIDAD IMPLEM. ]]+Tabla5[[#This Row],[PUNTOS IMPACTO ]],"")
A10: 78078872 | B10: Ivan Dario Babilonia Cordero | C10: 894 | D10: Producción | E10: Calificada | F10: 5000000 | G10: N/A | H10: C | I10: 0 | J10: 0.01 | K10: 0 | L10: 0.02 | M10: 0 | N10: =IF(Tabla5[[#This Row],[VALOR INVERSIÓN]]="","",IF(Tabla5[[#This Row],[VALOR INVERSIÓN]]<=10000000,100%*10%*22000,IF(AND(Tabla5[[#This Row],[VALOR INVERSIÓN]]>10000000,Tabla5[[#This Row],[VALOR INVERSIÓN]]<=20000000),60%*10%*22000,20%*10%*22000))) -> 2200 | O10: =IF(Tabla5[[#This Row],[ROI (MESES)]]="","",IF(Tabla5[[#This Row],[ROI (MESES)]]="N/A","0",IF(Tabla5[[#This Row],[ROI (MESES)]]="<=3",100%*10%*22000,IF(Tabla5[[#This Row],[ROI (MESES)]]=">3<=6",75%*10%*22000,25%*10%*22000)))) -> 0 | P10: =IF(Tabla5[[#This Row],[FACILIDAD IMPLEM.]]="","",IF(Tabla5[[#This Row],[FACILIDAD IMPLEM.]]="A",100%*10%*22000,IF(AND(Tabla5[[#This Row],[FACILIDAD IMPLEM.]]="B"),50%*10%*22000,20%*10%*22000))) -> 440 | Q10: =Tabla5[[#This Row],[IMPACTO AMBIENTAL (Máx. 25%)]]*70%*22000+Tabla5[[#This Row],[IMPACTO ECONÓMICO (Máx. 25%)]]*70%*22000+Tabla5[[#This Row],[IMPACTO SST (Máx. 20%)]]*70%*22000+Tabla5[[#This Row],[IMPACTO PRODUCTIVIDAD (Máx. 25%)]]*70%*22000+Tabla5[[#This Row],[IMPACTO ORDEN Y ASEO (Máx. 5%)]]*70%*22000 -> 462 | R10: =IFERROR(Tabla5[[#This Row],[PUNTOS VALOR INVERSIÓN]]+Tabla5[[#This Row],[PUNTOS ROI ]]+Tabla5[[#This Row],[PUNTOS FACILIDAD IMPLEM. ]]+Tabla5[[#This Row],[PUNTOS IMPACTO ]],"") -> 3102 | T10: Técnica G2 | U10: Baja | V10: Cambiar grapas de montaje por sistema fijo | W10: Pendiente pruebas | X10: No viable | Y10: Descartada
A11: 78078872 | B11: Ivan Dario Babilonia Cordero | C11: 895 | D11: Producción | E11: Descartada | N11: =IF(Tabla5[[#This Row],[VALOR INVERSIÓN]]="","",IF(Tabla5[[#This Row],[VALOR INVERSIÓN]]<=10000000,100%*10%*22000,IF(AND(Tabla5[[#This Row],[VALOR INVERSIÓN]]>10000000,Tabla5[[#This Row],[VALOR INVERSIÓN]]<=20000000),60%*10%*22000,20%*10%*22000))) | O11: =IF(Tabla5[[#This Row],[ROI (MESES)]]="","",IF(Tabla5[[#This Row],[ROI (MESES)]]="N/A","0",IF(Tabla5[[#This Row],[ROI (MESES)]]="<=3",100%*10%*22000,IF(Tabla5[[#This Row],[ROI (MESES)]]=">3<=6",75%*10%*22000,25%*10%*22000)))) | P11: =IF(Tabla5[[#This Row],[FACILIDAD IMPLEM.]]="","",IF(Tabla5[[#This Row],[FACILIDAD IMPLEM.]]="A",100%*10%*22000,IF(AND(Tabla5[[#This Row],[FACILIDAD IMPLEM.]]="B"),50%*10%*22000,20%*10%*22000))) | Q11: =Tabla5[[#This Row],[IMPACTO AMBIENTAL (Máx. 25%)]]*70%*22000+Tabla5[[#This Row],[IMPACTO ECONÓMICO (Máx. 25%)]]*70%*22000+Tabla5[[#This Row],[IMPACTO SST (Máx. 20%)]]*70%*22000+Tabla5[[#This Row],[IMPACTO PRODUCTIVIDAD (Máx. 25%)]]*70%*22000+Tabla5[[#This Row],[IMPACTO ORDEN Y ASEO (Máx. 5%)]]*70%*22000 -> 0 | R11: =IFERROR(Tabla5[[#This Row],[PUNTOS VALOR INVERSIÓN]]+Tabla5[[#This Row],[PUNTOS ROI ]]+Tabla5[[#This Row],[PUNTOS FACILIDAD IMPLEM. ]]+Tabla5[[#This Row],[PUNTOS IMPACTO ]],"")
A12: 1110570952 | B12: Andrés Felipe Ortega Rodríguez | C12: 949 | D12: Producción | E12: Descartada | N12: =IF(Tabla5[[#This Row],[VALOR INVERSIÓN]]="","",IF(Tabla5[[#This Row],[VALOR INVERSIÓN]]<=10000000,100%*10%*22000,IF(AND(Tabla5[[#This Row],[VALOR INVERSIÓN]]>10000000,Tabla5[[#This Row],[VALOR INVERSIÓN]]<=20000000),60%*10%*22000,20%*10%*22000))) | O12: =IF(Tabla5[[#This Row],[ROI (MESES)]]="","",IF(Tabla5[[#This Row],[ROI (MESES)]]="N/A","0",IF(Tabla5[[#This Row],[ROI (MESES)]]="<=3",100%*10%*22000,IF(Tabla5[[#This Row],[ROI (MESES)]]=">3<=6",75%*10%*22000,25%*10%*22000)))) | P12: =IF(Tabla5[[#This Row],[FACILIDAD IMPLEM.]]="","",IF(Tabla5[[#This Row],[FACILIDAD IMPLEM.]]="A",100%*10%*22000,IF(AND(Tabla5[[#This Row],[FACILIDAD IMPLEM.]]="B"),50%*10%*22000,20%*10%*22000))) | Q12: =Tabla5[[#This Row],[IMPACTO AMBIENTAL (Máx. 25%)]]*70%*22000+Tabla5[[#This Row],[IMPACTO ECONÓMICO (Máx. 25%)]]*70%*22000+Tabla5[[#This Row],[IMPACTO SST (Máx. 20%)]]*70%*22000+Tabla5[[#This Row],[IMPACTO PRODUCTIVIDAD (Máx. 25%)]]*70%*22000+Tabla5[[#This Row],[IMPACTO ORDEN Y ASEO (Máx. 5%)]]*70%*22000 -> 0 | R12: =IFERROR(Tabla5[[#This Row],[PUNTOS VALOR INVERSIÓN]]+Tabla5[[#This Row],[PUNTOS ROI ]]+Tabla5[[#This Row],[PUNTOS FACILIDAD IMPLEM. ]]+Tabla5[[#This Row],[PUNTOS IMPACTO ]],"")
A13: 71690439 | B13: Jhon Jairo Villamizar Gutierrez | C13: 963 | D13: Mantenimiento | E13: Calificada | F13: 1000000 | G13: N/A | H13: A | I13: 0 | J13: 0.025 | K13: 0 | L13: 0 | M13: 0 | N13: =IF(Tabla5[[#This Row],[VALOR INVERSIÓN]]="","",IF(Tabla5[[#This Row],[VALOR INVERSIÓN]]<=10000000,100%*10%*22000,IF(AND(Tabla5[[#This Row],[VALOR INVERSIÓN]]>10000000,Tabla5[[#This Row],[VALOR INVERSIÓN]]<=20000000),60%*10%*22000,20%*10%*22000))) -> 2200 | O13: =IF(Tabla5[[#This Row],[ROI (MESES)]]="","",IF(Tabla5[[#This Row],[ROI (MESES)]]="N/A","0",IF(Tabla5[[#This Row],[ROI (MESES)]]="<=3",100%*10%*22000,IF(Tabla5[[#This Row],[ROI (MESES)]]=">3<=6",75%*10%*22000,25%*10%*22000)))) -> 0 | P13: =IF(Tabla5[[#This Row],[FACILIDAD IMPLEM.]]="","",IF(Tabla5[[#This Row],[FACILIDAD IMPLEM.]]="A",100%*10%*22000,IF(AND(Tabla5[[#This Row],[FACILIDAD IMPLEM.]]="B"),50%*10%*22000,20%*10%*22000))) -> 2200 | Q13: =Tabla5[[#This Row],[IMPACTO AMBIENTAL (Máx. 25%)]]*70%*22000+Tabla5[[#This Row],[IMPACTO ECONÓMICO (Máx. 25%)]]*70%*22000+Tabla5[[#This Row],[IMPACTO SST (Máx. 20%)]]*70%*22000+Tabla5[[#This Row],[IMPACTO PRODUCTIVIDAD (Máx. 25%)]]*70%*22000+Tabla5[[#This Row],[IMPACTO ORDEN Y ASEO (Máx. 5%)]]*70%*22000 -> 385 | R13: =IFERROR(Tabla5[[#This Row],[PUNTOS VALOR INVERSIÓN]]+Tabla5[[#This Row],[PUNTOS ROI ]]+Tabla5[[#This Row],[PUNTOS FACILIDAD IMPLEM. ]]+Tabla5[[#This Row],[PUNTOS IMPACTO ]],"") -> 4785 | T13: Técnica G2 | U13: Baja | V13: Gancho de sostenimiento de botonera de diferencial de estación B en flama | W13: Ya se está implementando. | X13: Juan Manuel Aguinaga | Y13: En proceso
A14: 71690439 | B14: Jhon Jairo Villamizar Gutierrez | C14: 964 | D14: Mantenimiento | E14: Calificada | F14: 1000000 | G14: N/A | H14: B | I14: 0 | J14: 0.05 | K14: 0.12 | L14: 0 | M14: 0 | N14: =IF(Tabla5[[#This Row],[VALOR INVERSIÓN]]="","",IF(Tabla5[[#This Row],[VALOR INVERSIÓN]]<=10000000,100%*10%*22000,IF(AND(Tabla5[[#This Row],[VALOR INVERSIÓN]]>10000000,Tabla5[[#This Row],[VALOR INVERSIÓN]]<=20000000),60%*10%*22000,20%*10%*22000))) -> 2200 | O14: =IF(Tabla5[[#This Row],[ROI (MESES)]]="","",IF(Tabla5[[#This Row],[ROI (MESES)]]="N/A","0",IF(Tabla5[[#This Row],[ROI (MESES)]]="<=3",100%*10%*22000,IF(Tabla5[[#This Row],[ROI (MESES)]]=">3<=6",75%*10%*22000,25%*10%*22000)))) -> 0 | P14: =IF(Tabla5[[#This Row],[FACILIDAD IMPLEM.]]="","",IF(Tabla5[[#This Row],[FACILIDAD IMPLEM.]]="A",100%*10%*22000,IF(AND(Tabla5[[#This Row],[FACILIDAD IMPLEM.]]="B"),50%*10%*22000,20%*10%*22000))) -> 1100 | Q14: =Tabla5[[#This Row],[IMPACTO AMBIENTAL (Máx. 25%)]]*70%*22000+Tabla5[[#This Row],[IMPACTO ECONÓMICO (Máx. 25%)]]*70%*22000+Tabla5[[#This Row],[IMPACTO SST (Máx. 20%)]]*70%*22000+Tabla5[[#This Row],[IMPACTO PRODUCTIVIDAD (Máx. 25%)]]*70%*22000+Tabla5[[#This Row],[IMPACTO ORDEN Y ASEO (Máx. 5%)]]*70%*22000 -> 2618 | R14: =IFERROR(Tabla5[[#This Row],[PUNTOS VALOR INVERSIÓN]]+Tabla5[[#This Row],[PUNTOS ROI ]]+Tabla5[[#This Row],[PUNTOS FACILIDAD IMPLEM. ]]+Tabla5[[#This Row],[PUNTOS IMPACTO ]],"") -> 5918 | T14: Técnica G1 | U14: Baja | V14: Cambio de puerto de carga chisperos | W14: Al momento se tiene usa solucion temporal mientras se implementa el proceso HQ en todas las maquinas, Don Gustavo Ossa profundizara con Don Jhon Villamizar sobre el proceso del chispero | X14: No viable | Y14: Descartada
A15: 1047413742 | B15: Andrés Coneo | C15: 972 | D15: Mantenimiento | E15: Calificada | F15: 10000000 | G15: >6 | H15: C | I15: 0 | J15: 0.05 | K15: 0 | L15: 0 | M15: 0 | N15: =IF(Tabla5[[#This Row],[VALOR INVERSIÓN]]="","",IF(Tabla5[[#This Row],[VALOR INVERSIÓN]]<=10000000,100%*10%*22000,IF(AND(Tabla5[[#This Row],[VALOR INVERSIÓN]]>10000000,Tabla5[[#This Row],[VALOR INVERSIÓN]]<=20000000),60%*10%*22000,20%*10%*22000))) -> 2200 | O15: =IF(Tabla5[[#This Row],[ROI (MESES)]]="","",IF(Tabla5[[#This Row],[ROI (MESES)]]="N/A","0",IF(Tabla5[[#This Row],[ROI (MESES)]]="<=3",100%*10%*22000,IF(Tabla5[[#This Row],[ROI (MESES)]]=">3<=6",75%*10%*22000,25%*10%*22000)))) -> 550 | P15: =IF(Tabla5[[#This Row],[FACILIDAD IMPLEM.]]="","",IF(Tabla5[[#This Row],[FACILIDAD IMPLEM.]]="A",100%*10%*22000,IF(AND(Tabla5[[#This Row],[FACILIDAD IMPLEM.]]="B"),50%*10%*22000,20%*10%*22000))) -> 440 | Q15: =Tabla5[[#This Row],[IMPACTO AMBIENTAL (Máx. 25%)]]*70%*22000+Tabla5[[#This Row],[IMPACTO ECONÓMICO (Máx. 25%)]]*70%*22000+Tabla5[[#This Row],[IMPACTO SST (Máx. 20%)]]*70%*22000+Tabla5[[#This Row],[IMPACTO PRODUCTIVIDAD (Máx. 25%)]]*70%*22000+Tabla5[[#This Row],[IMPACTO ORDEN Y ASEO (Máx. 5%)]]*70%*22000 -> 770 | R15: =IFERROR(Tabla5[[#This Row],[PUNTOS VALOR INVERSIÓN]]+Tabla5[[#This Row],[PUNTOS ROI ]]+Tabla5[[#This Row],[PUNTOS FACILIDAD IMPLEM. ]]+Tabla5[[#This Row],[PUNTOS IMPACTO ]],"") -> 3960 | T15: Técnica G2 | U15: No Viable | V15: Control inalambrico para diferenciales | W15: Tiende a desaparecer con proyecto HQ | Y15: Descartada
A16: 1110570952 | B16: Andrés Felipe Ortega Rodríguez | C16: 977 | D16: Producción | E16: Descartada | N16: =IF(Tabla5[[#This Row],[VALOR INVERSIÓN]]="","",IF(Tabla5[[#This Row],[VALOR INVERSIÓN]]<=10000000,100%*10%*22000,IF(AND(Tabla5[[#This Row],[VALOR INVERSIÓN]]>10000000,Tabla5[[#This Row],[VALOR INVERSIÓN]]<=20000000),60%*10%*22000,20%*10%*22000))) | O16: =IF(Tabla5[[#This Row],[ROI (MESES)]]="","",IF(Tabla5[[#This Row],[ROI (MESES)]]="N/A","0",IF(Tabla5[[#This Row],[ROI (MESES)]]="<=3",100%*10%*22000,IF(Tabla5[[#This Row],[ROI (MESES)]]=">3<=6",75%*10%*22000,25%*10%*22000)))) | P16: =IF(Tabla5[[#This Row],[FACILIDAD IMPLEM.]]="","",IF(Tabla5[[#This Row],[FACILIDAD IMPLEM.]]="A",100%*10%*22000,IF(AND(Tabla5[[#This Row],[FACILIDAD IMPLEM.]]="B"),50%*10%*22000,20%*10%*22000))) | Q16: =Tabla5[[#This Row],[IMPACTO AMBIENTAL (Máx. 25%)]]*70%*22000+Tabla5[[#This Row],[IMPACTO ECONÓMICO (Máx. 25%)]]*70%*22000+Tabla5[[#This Row],[IMPACTO SST (Máx. 20%)]]*70%*22000+Tabla5[[#This Row],[IMPACTO PRODUCTIVIDAD (Máx. 25%)]]*70%*22000+Tabla5[[#This Row],[IMPACTO ORDEN Y ASEO (Máx. 5%)]]*70%*22000 -> 0 | R16: =IFERROR(Tabla5[[#This Row],[PUNTOS VALOR INVERSIÓN]]+Tabla5[[#This Row],[PUNTOS ROI ]]+Tabla5[[#This Row],[PUNTOS FACILIDAD IMPLEM. ]]+Tabla5[[#This Row],[PUNTOS IMPACTO ]],"")
A17: 1001812262 | B17: José Julián Betancur Estrada | C17: 4866 | D17: Producción | E17: Descartada | N17: =IF(Tabla5[[#This Row],[VALOR INVERSIÓN]]="","",IF(Tabla5[[#This Row],[VALOR INVERSIÓN]]<=10000000,100%*10%*22000,IF(AND(Tabla5[[#This Row],[VALOR INVERSIÓN]]>10000000,Tabla5[[#This Row],[VALOR INVERSIÓN]]<=20000000),60%*10%*22000,20%*10%*22000))) | O17: =IF(Tabla5[[#This Row],[ROI (MESES)]]="","",IF(Tabla5[[#This Row],[ROI (MESES)]]="N/A","0",IF(Tabla5[[#This Row],[ROI (MESES)]]="<=3",100%*10%*22000,IF(Tabla5[[#This Row],[ROI (MESES)]]=">3<=6",75%*10%*22000,25%*10%*22000)))) | P17: =IF(Tabla5[[#This Row],[FACILIDAD IMPLEM.]]="","",IF(Tabla5[[#This Row],[FACILIDAD IMPLEM.]]="A",100%*10%*22000,IF(AND(Tabla5[[#This Row],[FACILIDAD IMPLEM.]]="B"),50%*10%*22000,20%*10%*22000))) | Q17: =Tabla5[[#This Row],[IMPACTO AMBIENTAL (Máx. 25%)]]*70%*22000+Tabla5[[#This Row],[IMPACTO ECONÓMICO (Máx. 25%)]]*70%*22000+Tabla5[[#This Row],[IMPACTO SST (Máx. 20%)]]*70%*22000+Tabla5[[#This Row],[IMPACTO PRODUCTIVIDAD (Máx. 25%)]]*70%*22000+Tabla5[[#This Row],[IMPACTO ORDEN Y ASEO (Máx. 5%)]]*70%*22000 -> 0 | R17: =IFERROR(Tabla5[[#This Row],[PUNTOS VALOR INVERSIÓN]]+Tabla5[[#This Row],[PUNTOS ROI ]]+Tabla5[[#This Row],[PUNTOS FACILIDAD IMPLEM. ]]+Tabla5[[#This Row],[PUNTOS IMPACTO ]],"") | S17: 24/07/2024 Descartada. Es algo implementado y que se encuentra en proceso. 27/08/2024 03:46 pm Se habló con colaborador explicandole los motivos por los que no se tuvo en cuenta su idea, se contó con apoyo de Cristian Alzate
A18: 1001415647 | B18: Wilder Duvan Atehortua Iral | C18: 7424 | D18: Producción | E18: Calificada | F18: 3000000 | G18: >6 | H18: A | I18: 0 | J18: 0 | K18: 0.12 | L18: 0 | M18: 0.02 | N18: =IF(Tabla5[[#This Row],[VALOR INVERSIÓN]]="","",IF(Tabla5[[#This Row],[VALOR INVERSIÓN]]<=10000000,100%*10%*22000,IF(AND(Tabla5[[#This Row],[VALOR INVERSIÓN]]>10000000,Tabla5[[#This Row],[VALOR INVERSIÓN]]<=20000000),60%*10%*22000,20%*10%*22000))) -> 2200 | O18: =IF(Tabla5[[#This Row],[ROI (MESES)]]="","",IF(Tabla5[[#This Row],[ROI (MESES)]]="N/A","0",IF(Tabla5[[#This Row],[ROI (MESES)]]="<=3",100%*10%*22000,IF(Tabla5[[#This Row],[ROI (MESES)]]=">3<=6",75%*10%*22000,25%*10%*22000)))) -> 550 | P18: =IF(Tabla5[[#This Row],[FACILIDAD IMPLEM.]]="","",IF(Tabla5[[#This Row],[FACILIDAD IMPLEM.]]="A",100%*10%*22000,IF(AND(Tabla5[[#This Row],[FACILIDAD IMPLEM.]]="B"),50%*10%*22000,20%*10%*22000))) -> 2200 | Q18: =Tabla5[[#This Row],[IMPACTO AMBIENTAL (Máx. 25%)]]*70%*22000+Tabla5[[#This Row],[IMPACTO ECONÓMICO (Máx. 25%)]]*70%*22000+Tabla5[[#This Row],[IMPACTO SST (Máx. 20%)]]*70%*22000+Tabla5[[#This Row],[IMPACTO PRODUCTIVIDAD (Máx. 25%)]]*70%*22000+Tabla5[[#This Row],[IMPACTO ORDEN Y ASEO (Máx. 5%)]]*70%*22000 -> 2156 | R18: =IFERROR(Tabla5[[#This Row],[PUNTOS VALOR INVERSIÓN]]+Tabla5[[#This Row],[PUNTOS ROI ]]+Tabla5[[#This Row],[PUNTOS FACILIDAD IMPLEM. ]]+Tabla5[[#This Row],[PUNTOS IMPACTO ]],"") -> 7106 | T18: Técnica G1 | U18: Alta | V18: Lampara LED en forma de ARO | W18: Se va a validar luz tipo minero, hablar con SST | X18: Marcela Rios | Y18: En proceso
A19: 1026132871 | B19: Lyda Sorany Montoya Castaño | C19: 8060 | D19: Comercial | E19: Calificada | F19: 5000000 | G19: >6 | H19: B | I19: 0 | J19: 0.04 | K19: 0 | L19: 0 | M19: 0 | N19: =IF(Tabla5[[#This Row],[VALOR INVERSIÓN]]="","",IF(Tabla5[[#This Row],[VALOR INVERSIÓN]]<=10000000,100%*10%*22000,IF(AND(Tabla5[[#This Row],[VALOR INVERSIÓN]]>10000000,Tabla5[[#This Row],[VALOR INVERSIÓN]]<=20000000),60%*10%*22000,20%*10%*22000))) -> 2200 | O19: =IF(Tabla5[[#This Row],[ROI (MESES)]]="","",IF(Tabla5[[#This Row],[ROI (MESES)]]="N/A","0",IF(Tabla5[[#This Row],[ROI (MESES)]]="<=3",100%*10%*22000,IF(Tabla5[[#This Row],[ROI (MESES)]]=">3<=6",75%*10%*22000,25%*10%*22000)))) -> 550 | P19: =IF(Tabla5[[#This Row],[FACILIDAD IMPLEM.]]="","",IF(Tabla5[[#This Row],[FACILIDAD IMPLEM.]]="A",100%*10%*22000,IF(AND(Tabla5[[#This Row],[FACILIDAD IMPLEM.]]="B"),50%*10%*22000,20%*10%*22000))) -> 1100 | Q19: =Tabla5[[#This Row],[IMPACTO AMBIENTAL (Máx. 25%)]]*70%*22000+Tabla5[[#This Row],[IMPACTO ECONÓMICO (Máx. 25%)]]*70%*22000+Tabla5[[#This Row],[IMPACTO SST (Máx. 20%)]]*70%*22000+Tabla5[[#This Row],[IMPACTO PRODUCTIVIDAD (Máx. 25%)]]*70%*22000+Tabla5[[#This Row],[IMPACTO ORDEN Y ASEO (Máx. 5%)]]*70%*22000 -> 616 | R19: =IFERROR(Tabla5[[#This Row],[PUNTOS VALOR INVERSIÓN]]+Tabla5[[#This Row],[PUNTOS ROI ]]+Tabla5[[#This Row],[PUNTOS FACILIDAD IMPLEM. ]]+Tabla5[[#This Row],[PUNTOS IMPACTO ]],"") -> 4466 | S19: Reactivar bebedero caballo | T19: Comercial | U19: Alta | V19: Reactivar bebedero para caballo | W19: Revisar flotadores para relanzamiento de producto | X19: JuanDavid Rojas | Y19: En proceso
A20: 71175113 | B20: Diego León Vásques Cortés | C20: 4951 | D20: Producción | E20: Calificada | F20: 500000 | G20: <=3 | H20: A | I20: 0 | J20: 0 | K20: 0.08 | L20: 0 | M20: 0 | N20: =IF(Tabla5[[#This Row],[VALOR INVERSIÓN]]="","",IF(Tabla5[[#This Row],[VALOR INVERSIÓN]]<=10000000,100%*10%*22000,IF(AND(Tabla5[[#This Row],[VALOR INVERSIÓN]]>10000000,Tabla5[[#This Row],[VALOR INVERSIÓN]]<=20000000),60%*10%*22000,20%*10%*22000))) -> 2200 | O20: =IF(Tabla5[[#This Row],[ROI (MESES)]]="","",IF(Tabla5[[#This Row],[ROI (MESES)]]="N/A","0",IF(Tabla5[[#This Row],[ROI (MESES)]]="<=3",100%*10%*22000,IF(Tabla5[[#This Row],[ROI (MESES)]]=">3<=6",75%*10%*22000,25%*10%*22000)))) -> 2200 | P20: =IF(Tabla5[[#This Row],[FACILIDAD IMPLEM.]]="","",IF(Tabla5[[#This Row],[FACILIDAD IMPLEM.]]="A",100%*10%*22000,IF(AND(Tabla5[[#This Row],[FACILIDAD IMPLEM.]]="B"),50%*10%*22000,20%*10%*22000))) -> 2200 | Q20: =Tabla5[[#This Row],[IMPACTO AMBIENTAL (Máx. 25%)]]*70%*22000+Tabla5[[#This Row],[IMPACTO ECONÓMICO (Máx. 25%)]]*70%*22000+Tabla5[[#This Row],[IMPACTO SST (Máx. 20%)]]*70%*22000+Tabla5[[#This Row],[IMPACTO PRODUCTIVIDAD (Máx. 25%)]]*70%*22000+Tabla5[[#This Row],[IMPACTO ORDEN Y ASEO (Máx. 5%)]]*70%*22000 -> 1232 | R20: =IFERROR(Tabla5[[#This Row],[PUNTOS VALOR INVERSIÓN]]+Tabla5[[#This Row],[PUNTOS ROI ]]+Tabla5[[#This Row],[PUNTOS FACILIDAD IMPLEM. ]]+Tabla5[[#This Row],[PUNTOS IMPACTO ]],"") -> 7832 | S20: 24/07/2024 Puntuada | T20: Técnica G1 | U20: Alta | V20: Caja para evitar desconexión de herramientas | W20: Realizar un diseño y entregarselo al personal de ensamble/soldadura para que realicen las demas, hacer un inventario de cuantas se requieren (Diego Vasquez) | X20: Juan David Rojas - Gustavo Ossa | Y20: Implementada
A21: 1035913083 | B21: Maria Teresa Ríos Zapata | C21: 5469 | D21: Producción | E21: Calificada | F21: 1000000 | G21: N/A | H21: A | I21: 0 | J21: 0 | K21: 0.03 | L21: 0 | M21: 0 | N21: =IF(Tabla5[[#This Row],[VALOR INVERSIÓN]]="","",IF(Tabla5[[#This Row],[VALOR INVERSIÓN]]<=10000000,100%*10%*22000,IF(AND(Tabla5[[#This Row],[VALOR INVERSIÓN]]>10000000,Tabla5[[#This Row],[VALOR INVERSIÓN]]<=20000000),60%*10%*22000,20%*10%*22000))) -> 2200 | O21: =IF(Tabla5[[#This Row],[ROI (MESES)]]="","",IF(Tabla5[[#This Row],[ROI (MESES)]]="N/A","0",IF(Tabla5[[#This Row],[ROI (MESES)]]="<=3",100%*10%*22000,IF(Tabla5[[#This Row],[ROI (MESES)]]=">3<=6",75%*10%*22000,25%*10%*22000)))) -> 0 | P21: =IF(Tabla5[[#This Row],[FACILIDAD IMPLEM.]]="","",IF(Tabla5[[#This Row],[FACILIDAD IMPLEM.]]="A",100%*10%*22000,IF(AND(Tabla5[[#This Row],[FACILIDAD IMPLEM.]]="B"),50%*10%*22000,20%*10%*22000))) -> 2200 | Q21: =Tabla5[[#This Row],[IMPACTO AMBIENTAL (Máx. 25%)]]*70%*22000+Tabla5[[#This Row],[IMPACTO ECONÓMICO (Máx. 25%)]]*70%*22000+Tabla5[[#This Row],[IMPACTO SST (Máx. 20%)]]*70%*22000+Tabla5[[#This Row],[IMPACTO PRODUCTIVIDAD (Máx. 25%)]]*70%*22000+Tabla5[[#This Row],[IMPACTO ORDEN Y ASEO (Máx. 5%)]]*70%*22000 -> 462 | R21: =IFERROR(Tabla5[[#This Row],[PUNTOS VALOR INVERSIÓN]]+Tabla5[[#This Row],[PUNTOS ROI ]]+Tabla5[[#This Row],[PUNTOS FACILIDAD IMPLEM. ]]+Tabla5[[#This Row],[PUNTOS IMPACTO ]],"") -> 4862 | S21: 31/07/2024 Puntuada | T21: Técnica G2 | U21: No Viable | V21: Interruptor individual para los tomas de las herramientas. | W21: No es justificable la implememtación. | Y21: Descartada
A22: 1110570952 | B22: Andrés Felipe Ortega Rodríguez | C22: 5470 | D22: Producción | E22: Calificada | F22: 4000000 | G22: N/A | H22: A | I22: 0 | J22: 0 | K22: 0.07 | L22: 0 | M22: 0 | N22: =IF(Tabla5[[#This Row],[VALOR INVERSIÓN]]="","",IF(Tabla5[[#This Row],[VALOR INVERSIÓN]]<=10000000,100%*10%*22000,IF(AND(Tabla5[[#This Row],[VALOR INVERSIÓN]]>10000000,Tabla5[[#This Row],[VALOR INVERSIÓN]]<=20000000),60%*10%*22000,20%*10%*22000))) -> 2200 | O22: =IF(Tabla5[[#This Row],[ROI (MESES)]]="","",IF(Tabla5[[#This Row],[ROI (MESES)]]="N/A","0",IF(Tabla5[[#This Row],[ROI (MESES)]]="<=3",100%*10%*22000,IF(Tabla5[[#This Row],[ROI (MESES)]]=">3<=6",75%*10%*22000,25%*10%*22000)))) -> 0 | P22: =IF(Tabla5[[#This Row],[FACILIDAD IMPLEM.]]="","",IF(Tabla5[[#This Row],[FACILIDAD IMPLEM.]]="A",100%*10%*22000,IF(AND(Tabla5[[#This Row],[FACILIDAD IMPLEM.]]="B"),50%*10%*22000,20%*10%*22000))) -> 2200 | Q22: =Tabla5[[#This Row],[IMPACTO AMBIENTAL (Máx. 25%)]]*70%*22000+Tabla5[[#This Row],[IMPACTO ECONÓMICO (Máx. 25%)]]*70%*22000+Tabla5[[#This Row],[IMPACTO SST (Máx. 20%)]]*70%*22000+Tabla5[[#This Row],[IMPACTO PRODUCTIVIDAD (Máx. 25%)]]*70%*22000+Tabla5[[#This Row],[IMPACTO ORDEN Y ASEO (Máx. 5%)]]*70%*22000 -> 1078 | R22: =IFERROR(Tabla5[[#This Row],[PUNTOS VALOR INVERSIÓN]]+Tabla5[[#This Row],[PUNTOS ROI ]]+Tabla5[[#This Row],[PUNTOS FACILIDAD IMPLEM. ]]+Tabla5[[#This Row],[PUNTOS IMPACTO ]],"") -> 5478 | S22: 31/07/2024 Puntuada | T22: Comercial | U22: Media | V22: Rampa en caseta de control de ingreso | W22: Revisar con Jhon Jairo Henao para mejorar la entrada por la caseta de control aprovechando la pavimentación | X22: No Implementar | Y22: Descartada
A23: 71311035 | B23: Duverney Oquendo | C23: 7546 | D23: Producción | E23: Calificada | F23: 10000000 | G23: >6 | H23: B | I23: 0 | J23: 0.1 | K23: 0.07 | L23: 0.1 | M23: 0.02 | N23: =IF(Tabla5[[#This Row],[VALOR INVERSIÓN]]="","",IF(Tabla5[[#This Row],[VALOR INVERSIÓN]]<=10000000,100%*10%*22000,IF(AND(Tabla5[[#This Row],[VALOR INVERSIÓN]]>10000000,Tabla5[[#This Row],[VALOR INVERSIÓN]]<=20000000),60%*10%*22000,20%*10%*22000))) -> 2200 | O23: =IF(Tabla5[[#This Row],[ROI (MESES)]]="","",IF(Tabla5[[#This Row],[ROI (MESES)]]="N/A","0",IF(Tabla5[[#This Row],[ROI (MESES)]]="<=3",100%*10%*22000,IF(Tabla5[[#This Row],[ROI (MESES)]]=">3<=6",75%*10%*22000,25%*10%*22000)))) -> 550 | P23: =IF(Tabla5[[#This Row],[FACILIDAD IMPLEM.]]="","",IF(Tabla5[[#This Row],[FACILIDAD IMPLEM.]]="A",100%*10%*22000,IF(AND(Tabla5[[#This Row],[FACILIDAD IMPLEM.]]="B"),50%*10%*22000,20%*10%*22000))) -> 1100 | Q23: =Tabla5[[#This Row],[IMPACTO AMBIENTAL (Máx. 25%)]]*70%*22000+Tabla5[[#This Row],[IMPACTO ECONÓMICO (Máx. 25%)]]*70%*22000+Tabla5[[#This Row],[IMPACTO SST (Máx. 20%)]]*70%*22000+Tabla5[[#This Row],[IMPACTO PRODUCTIVIDAD (Máx. 25%)]]*70%*22000+Tabla5[[#This Row],[IMPACTO ORDEN Y ASEO (Máx. 5%)]]*70%*22000 -> 4466 | R23: =IFERROR(Tabla5[[#This Row],[PUNTOS VALOR INVERSIÓN]]+Tabla5[[#This Row],[PUNTOS ROI ]]+Tabla5[[#This Row],[PUNTOS FACILIDAD IMPLEM. ]]+Tabla5[[#This Row],[PUNTOS IMPACTO ]],"") -> 8316 | T23: Técnica G1 | U23: Alta | V23: Aislante para moldes de casillas | W23: Liderar Juan David Rojas y comercial, con el apoyo del proceso técnico. | X23: Juan David Rojas - Cristian Cardona | Y23: Implementada
A24: 1059704792 | B24: Jorge Eliecer Calderón Reyes | C24: 5918 | D24: G.Técnica | E24: Calificada | F24: 1500000 | G24: >3<=6 | H24: A | I24: 0.03 | J24: 0.09 | K24: 0 | L24: 0.03 | M24: 0 | N24: =IF(Tabla5[[#This Row],[VALOR INVERSIÓN]]="","",IF(Tabla5[[#This Row],[VALOR INVERSIÓN]]<=10000000,100%*10%*22000,IF(AND(Tabla5[[#This Row],[VALOR INVERSIÓN]]>10000000,Tabla5[[#This Row],[VALOR INVERSIÓN]]<=20000000),60%*10%*22000,20%*10%*22000))) -> 2200 | O24: =IF(Tabla5[[#This Row],[ROI (MESES)]]="","",IF(Tabla5[[#This Row],[ROI (MESES)]]="N/A","0",IF(Tabla5[[#This Row],[ROI (MESES)]]="<=3",100%*10%*22000,IF(Tabla5[[#This Row],[ROI (MESES)]]=">3<=6",75%*10%*22000,25%*10%*22000)))) -> 1650 | P24: =IF(Tabla5[[#This Row],[FACILIDAD IMPLEM.]]="","",IF(Tabla5[[#This Row],[FACILIDAD IMPLEM.]]="A",100%*10%*22000,IF(AND(Tabla5[[#This Row],[FACILIDAD IMPLEM.]]="B"),50%*10%*22000,20%*10%*22000))) -> 2200 | Q24: =Tabla5[[#This Row],[IMPACTO AMBIENTAL (Máx. 25%)]]*70%*22000+Tabla5[[#This Row],[IMPACTO ECONÓMICO (Máx. 25%)]]*70%*22000+Tabla5[[#This Row],[IMPACTO SST (Máx. 20%)]]*70%*22000+Tabla5[[#This Row],[IMPACTO PRODUCTIVIDAD (Máx. 25%)]]*70%*22000+Tabla5[[#This Row],[IMPACTO ORDEN Y ASEO (Máx. 5%)]]*70%*22000 -> 2310 | R24: =IFERROR(Tabla5[[#This Row],[PUNTOS VALOR INVERSIÓN]]+Tabla5[[#This Row],[PUNTOS ROI ]]+Tabla5[[#This Row],[PUNTOS FACILIDAD IMPLEM. ]]+Tabla5[[#This Row],[PUNTOS IMPACTO ]],"") -> 8360 | S24: 14/08/2024 Puntuada | T24: Técnica G1 | U24: Media | V24: Filtros para las flautas | W24: Hacer un rollo de malla que sirva de filtro dentro de la tuberia, para que la limalla no entre al racor | X24: Sebastián Ossa | Y24: En proceso
A25: 4116903 | B25: Luis Eduardo Perdomo Rojas | C25: 5919 | D25: Producción | E25: Descartada | N25: =IF(Tabla5[[#This Row],[VALOR INVERSIÓN]]="","",IF(Tabla5[[#This Row],[VALOR INVERSIÓN]]<=10000000,100%*10%*22000,IF(AND(Tabla5[[#This Row],[VALOR INVERSIÓN]]>10000000,Tabla5[[#This Row],[VALOR INVERSIÓN]]<=20000000),60%*10%*22000,20%*10%*22000))) | O25: =IF(Tabla5[[#This Row],[ROI (MESES)]]="","",IF(Tabla5[[#This Row],[ROI (MESES)]]="N/A","0",IF(Tabla5[[#This Row],[ROI (MESES)]]="<=3",100%*10%*22000,IF(Tabla5[[#This Row],[ROI (MESES)]]=">3<=6",75%*10%*22000,25%*10%*22000)))) | P25: =IF(Tabla5[[#This Row],[FACILIDAD IMPLEM.]]="","",IF(Tabla5[[#This Row],[FACILIDAD IMPLEM.]]="A",100%*10%*22000,IF(AND(Tabla5[[#This Row],[FACILIDAD IMPLEM.]]="B"),50%*10%*22000,20%*10%*22000))) | Q25: =Tabla5[[#This Row],[IMPACTO AMBIENTAL (Máx. 25%)]]*70%*22000+Tabla5[[#This Row],[IMPACTO ECONÓMICO (Máx. 25%)]]*70%*22000+Tabla5[[#This Row],[IMPACTO SST (Máx. 20%)]]*70%*22000+Tabla5[[#This Row],[IMPACTO PRODUCTIVIDAD (Máx. 25%)]]*70%*22000+Tabla5[[#This Row],[IMPACTO ORDEN Y ASEO (Máx. 5%)]]*70%*22000 -> 0 | R25: =IFERROR(Tabla5[[#This Row],[PUNTOS VALOR INVERSIÓN]]+Tabla5[[#This Row],[PUNTOS ROI ]]+Tabla5[[#This Row],[PUNTOS FACILIDAD IMPLEM. ]]+Tabla5[[#This Row],[PUNTOS IMPACTO ]],"") | S25: 14/08/2024 Descartada. 20/08/2024 09:20am Se habló con colaborador, se invitó a replantear ambas ideas, se contó con apoyo de Cristian Alzate
A26: 1000751888 | B26: Juan Camilo Agudelo Muñoz | C26: 5983 | D26: TI | E26: Calificada | F26: 6000000 | G26: >6 | H26: B | I26: 0 | J26: 0.14 | K26: 0 | L26: 0.06 | M26: 0 | N26: =IF(Tabla5[[#This Row],[VALOR INVERSIÓN]]="","",IF(Tabla5[[#This Row],[VALOR INVERSIÓN]]<=10000000,100%*10%*22000,IF(AND(Tabla5[[#This Row],[VALOR INVERSIÓN]]>10000000,Tabla5[[#This Row],[VALOR INVERSIÓN]]<=20000000),60%*10%*22000,20%*10%*22000))) -> 2200 | O26: =IF(Tabla5[[#This Row],[ROI (MESES)]]="","",IF(Tabla5[[#This Row],[ROI (MESES)]]="N/A","0",IF(Tabla5[[#This Row],[ROI (MESES)]]="<=3",100%*10%*22000,IF(Tabla5[[#This Row],[ROI (MESES)]]=">3<=6",75%*10%*22000,25%*10%*22000)))) -> 550 | P26: =IF(Tabla5[[#This Row],[FACILIDAD IMPLEM.]]="","",IF(Tabla5[[#This Row],[FACILIDAD IMPLEM.]]="A",100%*10%*22000,IF(AND(Tabla5[[#This Row],[FACILIDAD IMPLEM.]]="B"),50%*10%*22000,20%*10%*22000))) -> 1100 | Q26: =Tabla5[[#This Row],[IMPACTO AMBIENTAL (Máx. 25%)]]*70%*22000+Tabla5[[#This Row],[IMPACTO ECONÓMICO (Máx. 25%)]]*70%*22000+Tabla5[[#This Row],[IMPACTO SST (Máx. 20%)]]*70%*22000+Tabla5[[#This Row],[IMPACTO PRODUCTIVIDAD (Máx. 25%)]]*70%*22000+Tabla5[[#This Row],[IMPACTO ORDEN Y ASEO (Máx. 5%)]]*70%*22000 -> 3080 | R26: =IFERROR(Tabla5[[#This Row],[PUNTOS VALOR INVERSIÓN]]+Tabla5[[#This Row],[PUNTOS ROI ]]+Tabla5[[#This Row],[PUNTOS FACILIDAD IMPLEM. ]]+Tabla5[[#This Row],[PUNTOS IMPACTO ]],"") -> 6930 | S26: 21/08/2024 Pendiente evaluar costos de reposición de equipos con TI | T26: Técnica G1 | U26: Media | V26: Sistema Android para lectura de codigos en estampación | X26: Camilo Agudelo - Julián Giraldo | Y26: Sin empezar
A27: 71216235 | B27: Jorge Andrés Aguilar | C27: 5984 | D27: Producción | E27: Descartada | N27: =IF(Tabla5[[#This Row],[VALOR INVERSIÓN]]="","",IF(Tabla5[[#This Row],[VALOR INVERSIÓN]]<=10000000,100%*10%*22000,IF(AND(Tabla5[[#This Row],[VALOR INVERSIÓN]]>10000000,Tabla5[[#This Row],[VALOR INVERSIÓN]]<=20000000),60%*10%*22000,20%*10%*22000))) | O27: =IF(Tabla5[[#This Row],[ROI (MESES)]]="","",IF(Tabla5[[#This Row],[ROI (MESES)]]="N/A","0",IF(Tabla5[[#This Row],[ROI (MESES)]]="<=3",100%*10%*22000,IF(Tabla5[[#This Row],[ROI (MESES)]]=">3<=6",75%*10%*22000,25%*10%*22000)))) | P27: =IF(Tabla5[[#This Row],[FACILIDAD IMPLEM.]]="","",IF(Tabla5[[#This Row],[FACILIDAD IMPLEM.]]="A",100%*10%*22000,IF(AND(Tabla5[[#This Row],[FACILIDAD IMPLEM.]]="B"),50%*10%*22000,20%*10%*22000))) | Q27: =Tabla5[[#This Row],[IMPACTO AMBIENTAL (Máx. 25%)]]*70%*22000+Tabla5[[#This Row],[IMPACTO ECONÓMICO (Máx. 25%)]]*70%*22000+Tabla5[[#This Row],[IMPACTO SST (Máx. 20%)]]*70%*22000+Tabla5[[#This Row],[IMPACTO PRODUCTIVIDAD (Máx. 25%)]]*70%*22000+Tabla5[[#This Row],[IMPACTO ORDEN Y ASEO (Máx. 5%)]]*70%*22000 -> 0 | R27: =IFERROR(Tabla5[[#This Row],[PUNTOS VALOR INVERSIÓN]]+Tabla5[[#This Row],[PUNTOS ROI ]]+Tabla5[[#This Row],[PUNTOS FACILIDAD IMPLEM. ]]+Tabla5[[#This Row],[PUNTOS IMPACTO ]],"") | S27: 21/08/2024 Debe ampliar el concepto y validarse con SST, realizar pruebas.
A28: 1005346180 | B28: Diego Uribe Castellanos | C28: 6026 | D28: G.Técnica | E28: Calificada | F28: 1000000 | G28: <=3 | H28: A | I28: 0.16 | J28: 0.17 | K28: 0 | L28: 0.07 | M28: 0.03 | N28: =IF(Tabla5[[#This Row],[VALOR INVERSIÓN]]="","",IF(Tabla5[[#This Row],[VALOR INVERSIÓN]]<=10000000,100%*10%*22000,IF(AND(Tabla5[[#This Row],[VALOR INVERSIÓN]]>10000000,Tabla5[[#This Row],[VALOR INVERSIÓN]]<=20000000),60%*10%*22000,20%*10%*22000))) -> 2200 | O28: =IF(Tabla5[[#This Row],[ROI (MESES)]]="","",IF(Tabla5[[#This Row],[ROI (MESES)]]="N/A","0",IF(Tabla5[[#This Row],[ROI (MESES)]]="<=3",100%*10%*22000,IF(Tabla5[[#This Row],[ROI (MESES)]]=">3<=6",75%*10%*22000,25%*10%*22000)))) -> 2200 | P28: =IF(Tabla5[[#This Row],[FACILIDAD IMPLEM.]]="","",IF(Tabla5[[#This Row],[FACILIDAD IMPLEM.]]="A",100%*10%*22000,IF(AND(Tabla5[[#This Row],[FACILIDAD IMPLEM.]]="B"),50%*10%*22000,20%*10%*22000))) -> 2200 | Q28: =Tabla5[[#This Row],[IMPACTO AMBIENTAL (Máx. 25%)]]*70%*22000+Tabla5[[#This Row],[IMPACTO ECONÓMICO (Máx. 25%)]]*70%*22000+Tabla5[[#This Row],[IMPACTO SST (Máx. 20%)]]*70%*22000+Tabla5[[#This Row],[IMPACTO PRODUCTIVIDAD (Máx. 25%)]]*70%*22000+Tabla5[[#This Row],[IMPACTO ORDEN Y ASEO (Máx. 5%)]]*70%*22000 -> 6622 | R28: =IFERROR(Tabla5[[#This Row],[PUNTOS VALOR INVERSIÓN]]+Tabla5[[#This Row],[PUNTOS ROI ]]+Tabla5[[#This Row],[PUNTOS FACILIDAD IMPLEM. ]]+Tabla5[[#This Row],[PUNTOS IMPACTO ]],"") -> 13222 | S28: 21/08/2024 Puntuada. 24/02/2025 R. Jhon R | T28: Técnica G1 | U28: Baja | V28: Limpieza profunda de flautas y toberas | W28: Pendiente, no aplica realizar en la parada autonoma, sino en el plan de mantenimiento para realizarse por parte del operario y el MT. | X28: Sebastián Ossa | Y28: Sin empezar
A29: 1045047014 | B29: Juan Carlos Cano Ocampo | C29: 6057 | D29: Producción | E29: Descartada | N29: =IF(Tabla5[[#This Row],[VALOR INVERSIÓN]]="","",IF(Tabla5[[#This Row],[VALOR INVERSIÓN]]<=10000000,100%*10%*22000,IF(AND(Tabla5[[#This Row],[VALOR INVERSIÓN]]>10000000,Tabla5[[#This Row],[VALOR INVERSIÓN]]<=20000000),60%*10%*22000,20%*10%*22000))) | O29: =IF(Tabla5[[#This Row],[ROI (MESES)]]="","",IF(Tabla5[[#This Row],[ROI (MESES)]]="N/A","0",IF(Tabla5[[#This Row],[ROI (MESES)]]="<=3",100%*10%*22000,IF(Tabla5[[#This Row],[ROI (MESES)]]=">3<=6",75%*10%*22000,25%*10%*22000)))) | P29: =IF(Tabla5[[#This Row],[FACILIDAD IMPLEM.]]="","",IF(Tabla5[[#This Row],[FACILIDAD IMPLEM.]]="A",100%*10%*22000,IF(AND(Tabla5[[#This Row],[FACILIDAD IMPLEM.]]="B"),50%*10%*22000,20%*10%*22000))) | Q29: =Tabla5[[#This Row],[IMPACTO AMBIENTAL (Máx. 25%)]]*70%*22000+Tabla5[[#This Row],[IMPACTO ECONÓMICO (Máx. 25%)]]*70%*22000+Tabla5[[#This Row],[IMPACTO SST (Máx. 20%)]]*70%*22000+Tabla5[[#This Row],[IMPACTO PRODUCTIVIDAD (Máx. 25%)]]*70%*22000+Tabla5[[#This Row],[IMPACTO ORDEN Y ASEO (Máx. 5%)]]*70%*22000 -> 0 | R29: =IFERROR(Tabla5[[#This Row],[PUNTOS VALOR INVERSIÓN]]+Tabla5[[#This Row],[PUNTOS ROI ]]+Tabla5[[#This Row],[PUNTOS FACILIDAD IMPLEM. ]]+Tabla5[[#This Row],[PUNTOS IMPACTO ]],"") | S29: 03/09/2024 Descartada. 21/08/2024 Debe ampliar concepto de la idea. 28/08/2024 10:50am Se habló con colaborador, contando con acompañamiento de Crsitian Alzate. El colaborador solicita le concedan un espacio ya que tiene una presentación construída en power point para presentarla. 28/08/2024 Comité aprueba darle un espacio de 15 min en el proximo encuentro del 03/09/2024. 03/09/2024 Luego de sustentación comité considera idea como viable en el ambito de personas naturales, por lo cual no se puntuó, se decide que desde TH se revise la posibilidad de realizar un complemento enfocado en su experiencia y darle algún tipo de reconocimiento.
A30: 73570530 | B30: Jair José Aguilar Mora | C30: 6071 | D30: Producción | E30: Descartada | N30: =IF(Tabla5[[#This Row],[VALOR INVERSIÓN]]="","",IF(Tabla5[[#This Row],[VALOR INVERSIÓN]]<=10000000,100%*10%*22000,IF(AND(Tabla5[[#This Row],[VALOR INVERSIÓN]]>10000000,Tabla5[[#This Row],[VALOR INVERSIÓN]]<=20000000),60%*10%*22000,20%*10%*22000))) | O30: =IF(Tabla5[[#This Row],[ROI (MESES)]]="","",IF(Tabla5[[#This Row],[ROI (MESES)]]="N/A","0",IF(Tabla5[[#This Row],[ROI (MESES)]]="<=3",100%*10%*22000,IF(Tabla5[[#This Row],[ROI (MESES)]]=">3<=6",75%*10%*22000,25%*10%*22000)))) | P30: =IF(Tabla5[[#This Row],[FACILIDAD IMPLEM.]]="","",IF(Tabla5[[#This Row],[FACILIDAD IMPLEM.]]="A",100%*10%*22000,IF(AND(Tabla5[[#This Row],[FACILIDAD IMPLEM.]]="B"),50%*10%*22000,20%*10%*22000))) | Q30: =Tabla5[[#This Row],[IMPACTO AMBIENTAL (Máx. 25%)]]*70%*22000+Tabla5[[#This Row],[IMPACTO ECONÓMICO (Máx. 25%)]]*70%*22000+Tabla5[[#This Row],[IMPACTO SST (Máx. 20%)]]*70%*22000+Tabla5[[#This Row],[IMPACTO PRODUCTIVIDAD (Máx. 25%)]]*70%*22000+Tabla5[[#This Row],[IMPACTO ORDEN Y ASEO (Máx. 5%)]]*70%*22000 -> 0 | R30: =IFERROR(Tabla5[[#This Row],[PUNTOS VALOR INVERSIÓN]]+Tabla5[[#This Row],[PUNTOS ROI ]]+Tabla5[[#This Row],[PUNTOS FACILIDAD IMPLEM. ]]+Tabla5[[#This Row],[PUNTOS IMPACTO ]],"") | S30: 21/08/2024 Descartada. Técnicamente un extractor no retira calor por radiación. Pendiente hablar con operario.
A31: 1001416385 | B31: Duván Arley López Jiménez | C31: 6223 | D31: T.Humano | E31: Descartada | N31: =IF(Tabla5[[#This Row],[VALOR INVERSIÓN]]="","",IF(Tabla5[[#This Row],[VALOR INVERSIÓN]]<=10000000,100%*10%*22000,IF(AND(Tabla5[[#This Row],[VALOR INVERSIÓN]]>10000000,Tabla5[[#This Row],[VALOR INVERSIÓN]]<=20000000),60%*10%*22000,20%*10%*22000))) | O31: =IF(Tabla5[[#This Row],[ROI (MESES)]]="","",IF(Tabla5[[#This Row],[ROI (MESES)]]="N/A","0",IF(Tabla5[[#This Row],[ROI (MESES)]]="<=3",100%*10%*22000,IF(Tabla5[[#This Row],[ROI (MESES)]]=">3<=6",75%*10%*22000,25%*10%*22000)))) | P31: =IF(Tabla5[[#This Row],[FACILIDAD IMPLEM.]]="","",IF(Tabla5[[#This Row],[FACILIDAD IMPLEM.]]="A",100%*10%*22000,IF(AND(Tabla5[[#This Row],[FACILIDAD IMPLEM.]]="B"),50%*10%*22000,20%*10%*22000))) | Q31: =Tabla5[[#This Row],[IMPACTO AMBIENTAL (Máx. 25%)]]*70%*22000+Tabla5[[#This Row],[IMPACTO ECONÓMICO (Máx. 25%)]]*70%*22000+Tabla5[[#This Row],[IMPACTO SST (Máx. 20%)]]*70%*22000+Tabla5[[#This Row],[IMPACTO PRODUCTIVIDAD (Máx. 25%)]]*70%*22000+Tabla5[[#This Row],[IMPACTO ORDEN Y ASEO (Máx. 5%)]]*70%*22000 -> 0 | R31: =IFERROR(Tabla5[[#This Row],[PUNTOS VALOR INVERSIÓN]]+Tabla5[[#This Row],[PUNTOS ROI ]]+Tabla5[[#This Row],[PUNTOS FACILIDAD IMPLEM. ]]+Tabla5[[#This Row],[PUNTOS IMPACTO ]],"") | S31: 28/08/2024 Se debe revisar PNC de máquinas 8 y 17 con Sebastián Gallego para validar la necesidad y viabilidad de esta idea.
A32: 1128479264 | B32: Luis Carlos Ramos Rangel | C32: 6226 | D32: G.Técnica | E32: Descartada | N32: =IF(Tabla5[[#This Row],[VALOR INVERSIÓN]]="","",IF(Tabla5[[#This Row],[VALOR INVERSIÓN]]<=10000000,100%*10%*22000,IF(AND(Tabla5[[#This Row],[VALOR INVERSIÓN]]>10000000,Tabla5[[#This Row],[VALOR INVERSIÓN]]<=20000000),60%*10%*22000,20%*10%*22000))) | O32: =IF(Tabla5[[#This Row],[ROI (MESES)]]="","",IF(Tabla5[[#This Row],[ROI (MESES)]]="N/A","0",IF(Tabla5[[#This Row],[ROI (MESES)]]="<=3",100%*10%*22000,IF(Tabla5[[#This Row],[ROI (MESES)]]=">3<=6",75%*10%*22000,25%*10%*22000)))) | P32: =IF(Tabla5[[#This Row],[FACILIDAD IMPLEM.]]="","",IF(Tabla5[[#This Row],[FACILIDAD IMPLEM.]]="A",100%*10%*22000,IF(AND(Tabla5[[#This Row],[FACILIDAD IMPLEM.]]="B"),50%*10%*22000,20%*10%*22000))) | Q32: =Tabla5[[#This Row],[IMPACTO AMBIENTAL (Máx. 25%)]]*70%*22000+Tabla5[[#This Row],[IMPACTO ECONÓMICO (Máx. 25%)]]*70%*22000+Tabla5[[#This Row],[IMPACTO SST (Máx. 20%)]]*70%*22000+Tabla5[[#This Row],[IMPACTO PRODUCTIVIDAD (Máx. 25%)]]*70%*22000+Tabla5[[#This Row],[IMPACTO ORDEN Y ASEO (Máx. 5%)]]*70%*22000 -> 0 | R32: =IFERROR(Tabla5[[#This Row],[PUNTOS VALOR INVERSIÓN]]+Tabla5[[#This Row],[PUNTOS ROI ]]+Tabla5[[#This Row],[PUNTOS FACILIDAD IMPLEM. ]]+Tabla5[[#This Row],[PUNTOS IMPACTO ]],"") | S32: 28/08/2024 Descartada. La implementación de las OT aún se encuentra en proceso de ajustes y son temas que se están revisando.
A33: 1035919597 | B33: Sebastián Ossa Londoño | C33: 6240 | D33: Producción | E33: Calificada | F33: 100000 | G33: <=3 | H33: A | I33: 0.1 | J33: 0.07 | K33: 0.05 | L33: 0.2 | M33: 0.03 | N33: =IF(Tabla5[[#This Row],[VALOR INVERSIÓN]]="","",IF(Tabla5[[#This Row],[VALOR INVERSIÓN]]<=10000000,100%*10%*22000,IF(AND(Tabla5[[#This Row],[VALOR INVERSIÓN]]>10000000,Tabla5[[#This Row],[VALOR INVERSIÓN]]<=20000000),60%*10%*22000,20%*10%*22000))) -> 2200 | O33: =IF(Tabla5[[#This Row],[ROI (MESES)]]="","",IF(Tabla5[[#This Row],[ROI (MESES)]]="N/A","0",IF(Tabla5[[#This Row],[ROI (MESES)]]="<=3",100%*10%*22000,IF(Tabla5[[#This Row],[ROI (MESES)]]=">3<=6",75%*10%*22000,25%*10%*22000)))) -> 2200 | P33: =IF(Tabla5[[#This Row],[FACILIDAD IMPLEM.]]="","",IF(Tabla5[[#This Row],[FACILIDAD IMPLEM.]]="A",100%*10%*22000,IF(AND(Tabla5[[#This Row],[FACILIDAD IMPLEM.]]="B"),50%*10%*22000,20%*10%*22000))) -> 2200 | Q33: =Tabla5[[#This Row],[IMPACTO AMBIENTAL (Máx. 25%)]]*70%*22000+Tabla5[[#This Row],[IMPACTO ECONÓMICO (Máx. 25%)]]*70%*22000+Tabla5[[#This Row],[IMPACTO SST (Máx. 20%)]]*70%*22000+Tabla5[[#This Row],[IMPACTO PRODUCTIVIDAD (Máx. 25%)]]*70%*22000+Tabla5[[#This Row],[IMPACTO ORDEN Y ASEO (Máx. 5%)]]*70%*22000 -> 6930 | R33: =IFERROR(Tabla5[[#This Row],[PUNTOS VALOR INVERSIÓN]]+Tabla5[[#This Row],[PUNTOS ROI ]]+Tabla5[[#This Row],[PUNTOS FACILIDAD IMPLEM. ]]+Tabla5[[#This Row],[PUNTOS IMPACTO ]],"") -> 13530 | S33: 28/08/2024 Se deben realizar pruebas, seguimiento y validar. componentes químicos. 24/02/2025 Se continuarán buscando alternativas. R. Jhon R. | T33: Técnica G1 | U33: Media | V33: Soldadura fria o pegamento epóxico para los poros de los moldes | W33: Don John solicitara a sebastian continuar con los ensayos de este o un homologo para validar eficiencia | X33: No Implementar | Y33: Descartada
A34: 1128479264 | B34: Luis Carlos Ramos Rangel | C34: 6252 | D34: G.Técnica | E34: Calificada | F34: 1000000 | G34: N/A | H34: A | I34: 0.04 | J34: 0 | K34: 0 | L34: 0 | M34: 0.01 | N34: =IF(Tabla5[[#This Row],[VALOR INVERSIÓN]]="","",IF(Tabla5[[#This Row],[VALOR INVERSIÓN]]<=10000000,100%*10%*22000,IF(AND(Tabla5[[#This Row],[VALOR INVERSIÓN]]>10000000,Tabla5[[#This Row],[VALOR INVERSIÓN]]<=20000000),60%*10%*22000,20%*10%*22000))) -> 2200 | O34: =IF(Tabla5[[#This Row],[ROI (MESES)]]="","",IF(Tabla5[[#This Row],[ROI (MESES)]]="N/A","0",IF(Tabla5[[#This Row],[ROI (MESES)]]="<=3",100%*10%*22000,IF(Tabla5[[#This Row],[ROI (MESES)]]=">3<=6",75%*10%*22000,25%*10%*22000)))) -> 0 | P34: =IF(Tabla5[[#This Row],[FACILIDAD IMPLEM.]]="","",IF(Tabla5[[#This Row],[FACILIDAD IMPLEM.]]="A",100%*10%*22000,IF(AND(Tabla5[[#This Row],[FACILIDAD IMPLEM.]]="B"),50%*10%*22000,20%*10%*22000))) -> 2200 | Q34: =Tabla5[[#This Row],[IMPACTO AMBIENTAL (Máx. 25%)]]*70%*22000+Tabla5[[#This Row],[IMPACTO ECONÓMICO (Máx. 25%)]]*70%*22000+Tabla5[[#This Row],[IMPACTO SST (Máx. 20%)]]*70%*22000+Tabla5[[#This Row],[IMPACTO PRODUCTIVIDAD (Máx. 25%)]]*70%*22000+Tabla5[[#This Row],[IMPACTO ORDEN Y ASEO (Máx. 5%)]]*70%*22000 -> 770 | R34: =IFERROR(Tabla5[[#This Row],[PUNTOS VALOR INVERSIÓN]]+Tabla5[[#This Row],[PUNTOS ROI ]]+Tabla5[[#This Row],[PUNTOS FACILIDAD IMPLEM. ]]+Tabla5[[#This Row],[PUNTOS IMPACTO ]],"") -> 5170 | S34: 28/08/2024 Puntuada | T34: Técnica G2 | U34: No Viable | V34: Recipientes para material contaminado por planta | W34: No se soluciona nigún problema con la propuesta | Y34: Descartada
A35: 1035918433 | B35: Mateo Arango Betancur | C35: 6254 | D35: Producción | E35: Descartada | N35: =IF(Tabla5[[#This Row],[VALOR INVERSIÓN]]="","",IF(Tabla5[[#This Row],[VALOR INVERSIÓN]]<=10000000,100%*10%*22000,IF(AND(Tabla5[[#This Row],[VALOR INVERSIÓN]]>10000000,Tabla5[[#This Row],[VALOR INVERSIÓN]]<=20000000),60%*10%*22000,20%*10%*22000))) | O35: =IF(Tabla5[[#This Row],[ROI (MESES)]]="","",IF(Tabla5[[#This Row],[ROI (MESES)]]="N/A","0",IF(Tabla5[[#This Row],[ROI (MESES)]]="<=3",100%*10%*22000,IF(Tabla5[[#This Row],[ROI (MESES)]]=">3<=6",75%*10%*22000,25%*10%*22000)))) | P35: =IF(Tabla5[[#This Row],[FACILIDAD IMPLEM.]]="","",IF(Tabla5[[#This Row],[FACILIDAD IMPLEM.]]="A",100%*10%*22000,IF(AND(Tabla5[[#This Row],[FACILIDAD IMPLEM.]]="B"),50%*10%*22000,20%*10%*22000))) | Q35: =Tabla5[[#This Row],[IMPACTO AMBIENTAL (Máx. 25%)]]*70%*22000+Tabla5[[#This Row],[IMPACTO ECONÓMICO (Máx. 25%)]]*70%*22000+Tabla5[[#This Row],[IMPACTO SST (Máx. 20%)]]*70%*22000+Tabla5[[#This Row],[IMPACTO PRODUCTIVIDAD (Máx. 25%)]]*70%*22000+Tabla5[[#This Row],[IMPACTO ORDEN Y ASEO (Máx. 5%)]]*70%*22000 -> 0 | R35: =IFERROR(Tabla5[[#This Row],[PUNTOS VALOR INVERSIÓN]]+Tabla5[[#This Row],[PUNTOS ROI ]]+Tabla5[[#This Row],[PUNTOS FACILIDAD IMPLEM. ]]+Tabla5[[#This Row],[PUNTOS IMPACTO ]],"") | S35: 28/08/2024 Se debe validar funcionalidad y eficacia en el proceso. 9/12/2024 Luego de realizar las pruebas, SST la descarta porque se genera material particulado lo cual afectarías las zonas aledañas y se debería hacer un encerramiento, lo cual conlleva mas inversión.
A36: 1065659658 | B36: Roberto Carlos Rodríguez | C36: 6255 | D36: Producción | E36: Calificada | F36: 1000000 | G36: >6 | H36: B | I36: 0 | J36: 0.04 | K36: 0.01 | L36: 0.02 | M36: 0 | N36: =IF(Tabla5[[#This Row],[VALOR INVERSIÓN]]="","",IF(Tabla5[[#This Row],[VALOR INVERSIÓN]]<=10000000,100%*10%*22000,IF(AND(Tabla5[[#This Row],[VALOR INVERSIÓN]]>10000000,Tabla5[[#This Row],[VALOR INVERSIÓN]]<=20000000),60%*10%*22000,20%*10%*22000))) -> 2200 | O36: =IF(Tabla5[[#This Row],[ROI (MESES)]]="","",IF(Tabla5[[#This Row],[ROI (MESES)]]="N/A","0",IF(Tabla5[[#This Row],[ROI (MESES)]]="<=3",100%*10%*22000,IF(Tabla5[[#This Row],[ROI (MESES)]]=">3<=6",75%*10%*22000,25%*10%*22000)))) -> 550 | P36: =IF(Tabla5[[#This Row],[FACILIDAD IMPLEM.]]="","",IF(Tabla5[[#This Row],[FACILIDAD IMPLEM.]]="A",100%*10%*22000,IF(AND(Tabla5[[#This Row],[FACILIDAD IMPLEM.]]="B"),50%*10%*22000,20%*10%*22000))) -> 1100 | Q36: =Tabla5[[#This Row],[IMPACTO AMBIENTAL (Máx. 25%)]]*70%*22000+Tabla5[[#This Row],[IMPACTO ECONÓMICO (Máx. 25%)]]*70%*22000+Tabla5[[#This Row],[IMPACTO SST (Máx. 20%)]]*70%*22000+Tabla5[[#This Row],[IMPACTO PRODUCTIVIDAD (Máx. 25%)]]*70%*22000+Tabla5[[#This Row],[IMPACTO ORDEN Y ASEO (Máx. 5%)]]*70%*22000 -> 1078 | R36: =IFERROR(Tabla5[[#This Row],[PUNTOS VALOR INVERSIÓN]]+Tabla5[[#This Row],[PUNTOS ROI ]]+Tabla5[[#This Row],[PUNTOS FACILIDAD IMPLEM. ]]+Tabla5[[#This Row],[PUNTOS IMPACTO ]],"") -> 4928 | S36: 28/08/2024 Puntuada | T36: Técnica G2 | U36: No Viable | V36: Pines de patineta para regular ajuste de flautas | W36: No es optimo para el proceso. | Y36: Descartada
A37: 17685011 | B37: Alfredo Trujillo Cordoba | C37: 6262 | D37: G.Técnica | E37: Descartada | N37: =IF(Tabla5[[#This Row],[VALOR INVERSIÓN]]="","",IF(Tabla5[[#This Row],[VALOR INVERSIÓN]]<=10000000,100%*10%*22000,IF(AND(Tabla5[[#This Row],[VALOR INVERSIÓN]]>10000000,Tabla5[[#This Row],[VALOR INVERSIÓN]]<=20000000),60%*10%*22000,20%*10%*22000))) | O37: =IF(Tabla5[[#This Row],[ROI (MESES)]]="","",IF(Tabla5[[#This Row],[ROI (MESES)]]="N/A","0",IF(Tabla5[[#This Row],[ROI (MESES)]]="<=3",100%*10%*22000,IF(Tabla5[[#This Row],[ROI (MESES)]]=">3<=6",75%*10%*22000,25%*10%*22000)))) | P37: =IF(Tabla5[[#This Row],[FACILIDAD IMPLEM.]]="","",IF(Tabla5[[#This Row],[FACILIDAD IMPLEM.]]="A",100%*10%*22000,IF(AND(Tabla5[[#This Row],[FACILIDAD IMPLEM.]]="B"),50%*10%*22000,20%*10%*22000))) | Q37: =Tabla5[[#This Row],[IMPACTO AMBIENTAL (Máx. 25%)]]*70%*22000+Tabla5[[#This Row],[IMPACTO ECONÓMICO (Máx. 25%)]]*70%*22000+Tabla5[[#This Row],[IMPACTO SST (Máx. 20%)]]*70%*22000+Tabla5[[#This Row],[IMPACTO PRODUCTIVIDAD (Máx. 25%)]]*70%*22000+Tabla5[[#This Row],[IMPACTO ORDEN Y ASEO (Máx. 5%)]]*70%*22000 -> 0 | R37: =IFERROR(Tabla5[[#This Row],[PUNTOS VALOR INVERSIÓN]]+Tabla5[[#This Row],[PUNTOS ROI ]]+Tabla5[[#This Row],[PUNTOS FACILIDAD IMPLEM. ]]+Tabla5[[#This Row],[PUNTOS IMPACTO ]],"") | S37: 03/09/2024 Validar con Jhony Tuberquia
A38: 17685011 | B38: Alfredo Trujillo Cordoba | C38: 6263 | D38: G.Técnica | E38: Calificada | F38: 10000000 | G38: >6 | H38: A | I38: 0.1 | J38: 0.05 | K38: 0.02 | L38: 0.1 | M38: 0.05 | N38: =IF(Tabla5[[#This Row],[VALOR INVERSIÓN]]="","",IF(Tabla5[[#This Row],[VALOR INVERSIÓN]]<=10000000,100%*10%*22000,IF(AND(Tabla5[[#This Row],[VALOR INVERSIÓN]]>10000000,Tabla5[[#This Row],[VALOR INVERSIÓN]]<=20000000),60%*10%*22000,20%*10%*22000))) -> 2200 | O38: =IF(Tabla5[[#This Row],[ROI (MESES)]]="","",IF(Tabla5[[#This Row],[ROI (MESES)]]="N/A","0",IF(Tabla5[[#This Row],[ROI (MESES)]]="<=3",100%*10%*22000,IF(Tabla5[[#This Row],[ROI (MESES)]]=">3<=6",75%*10%*22000,25%*10%*22000)))) -> 550 | P38: =IF(Tabla5[[#This Row],[FACILIDAD IMPLEM.]]="","",IF(Tabla5[[#This Row],[FACILIDAD IMPLEM.]]="A",100%*10%*22000,IF(AND(Tabla5[[#This Row],[FACILIDAD IMPLEM.]]="B"),50%*10%*22000,20%*10%*22000))) -> 2200 | Q38: =Tabla5[[#This Row],[IMPACTO AMBIENTAL (Máx. 25%)]]*70%*22000+Tabla5[[#This Row],[IMPACTO ECONÓMICO (Máx. 25%)]]*70%*22000+Tabla5[[#This Row],[IMPACTO SST (Máx. 20%)]]*70%*22000+Tabla5[[#This Row],[IMPACTO PRODUCTIVIDAD (Máx. 25%)]]*70%*22000+Tabla5[[#This Row],[IMPACTO ORDEN Y ASEO (Máx. 5%)]]*70%*22000 -> 4928 | R38: =IFERROR(Tabla5[[#This Row],[PUNTOS VALOR INVERSIÓN]]+Tabla5[[#This Row],[PUNTOS ROI ]]+Tabla5[[#This Row],[PUNTOS FACILIDAD IMPLEM. ]]+Tabla5[[#This Row],[PUNTOS IMPACTO ]],"") -> 9878 | S38: 03/09/2024 Validar con Jhony Tuberquia | T38: Técnica G1 | U38: No Viable | V38: Mamparas entre cajas de materia prima | W38: Definir con mantenimiento fabricación | Y38: Descartada
A39: 1045047014 | B39: Juan Carlos Cano Ocampo | C39: 6376 | D39: Producción | E39: Descartada | N39: =IF(Tabla5[[#This Row],[VALOR INVERSIÓN]]="","",IF(Tabla5[[#This Row],[VALOR INVERSIÓN]]<=10000000,100%*10%*22000,IF(AND(Tabla5[[#This Row],[VALOR INVERSIÓN]]>10000000,Tabla5[[#This Row],[VALOR INVERSIÓN]]<=20000000),60%*10%*22000,20%*10%*22000))) | O39: =IF(Tabla5[[#This Row],[ROI (MESES)]]="","",IF(Tabla5[[#This Row],[ROI (MESES)]]="N/A","0",IF(Tabla5[[#This Row],[ROI (MESES)]]="<=3",100%*10%*22000,IF(Tabla5[[#This Row],[ROI (MESES)]]=">3<=6",75%*10%*22000,25%*10%*22000)))) | P39: =IF(Tabla5[[#This Row],[FACILIDAD IMPLEM.]]="","",IF(Tabla5[[#This Row],[FACILIDAD IMPLEM.]]="A",100%*10%*22000,IF(AND(Tabla5[[#This Row],[FACILIDAD IMPLEM.]]="B"),50%*10%*22000,20%*10%*22000))) | Q39: =Tabla5[[#This Row],[IMPACTO AMBIENTAL (Máx. 25%)]]*70%*22000+Tabla5[[#This Row],[IMPACTO ECONÓMICO (Máx. 25%)]]*70%*22000+Tabla5[[#This Row],[IMPACTO SST (Máx. 20%)]]*70%*22000+Tabla5[[#This Row],[IMPACTO PRODUCTIVIDAD (Máx. 25%)]]*70%*22000+Tabla5[[#This Row],[IMPACTO ORDEN Y ASEO (Máx. 5%)]]*70%*22000 -> 0 | R39: =IFERROR(Tabla5[[#This Row],[PUNTOS VALOR INVERSIÓN]]+Tabla5[[#This Row],[PUNTOS ROI ]]+Tabla5[[#This Row],[PUNTOS FACILIDAD IMPLEM. ]]+Tabla5[[#This Row],[PUNTOS IMPACTO ]],"") | S39: 03/09/2024 Descartada. Lo que propone es lo que se hace actualmente desde proceso comercial.
A40: 1128479264 | B40: Luis Carlos Ramos Rangel | C40: 6377 | D40: G.Técnica | E40: Descartada | N40: =IF(Tabla5[[#This Row],[VALOR INVERSIÓN]]="","",IF(Tabla5[[#This Row],[VALOR INVERSIÓN]]<=10000000,100%*10%*22000,IF(AND(Tabla5[[#This Row],[VALOR INVERSIÓN]]>10000000,Tabla5[[#This Row],[VALOR INVERSIÓN]]<=20000000),60%*10%*22000,20%*10%*22000))) | O40: =IF(Tabla5[[#This Row],[ROI (MESES)]]="","",IF(Tabla5[[#This Row],[ROI (MESES)]]="N/A","0",IF(Tabla5[[#This Row],[ROI (MESES)]]="<=3",100%*10%*22000,IF(Tabla5[[#This Row],[ROI (MESES)]]=">3<=6",75%*10%*22000,25%*10%*22000)))) | P40: =IF(Tabla5[[#This Row],[FACILIDAD IMPLEM.]]="","",IF(Tabla5[[#This Row],[FACILIDAD IMPLEM.]]="A",100%*10%*22000,IF(AND(Tabla5[[#This Row],[FACILIDAD IMPLEM.]]="B"),50%*10%*22000,20%*10%*22000))) | Q40: =Tabla5[[#This Row],[IMPACTO AMBIENTAL (Máx. 25%)]]*70%*22000+Tabla5[[#This Row],[IMPACTO ECONÓMICO (Máx. 25%)]]*70%*22000+Tabla5[[#This Row],[IMPACTO SST (Máx. 20%)]]*70%*22000+Tabla5[[#This Row],[IMPACTO PRODUCTIVIDAD (Máx. 25%)]]*70%*22000+Tabla5[[#This Row],[IMPACTO ORDEN Y ASEO (Máx. 5%)]]*70%*22000 -> 0 | R40: =IFERROR(Tabla5[[#This Row],[PUNTOS VALOR INVERSIÓN]]+Tabla5[[#This Row],[PUNTOS ROI ]]+Tabla5[[#This Row],[PUNTOS FACILIDAD IMPLEM. ]]+Tabla5[[#This Row],[PUNTOS IMPACTO ]],"") | S40: 03/09/2024 Descartada. Lo que propone fue una idea surgida e implementada en la zona de respeto.
A41: 3378476 | B41: Román José Dario Briñez Boscán | C41: 6397 | D41: G.Técnica | E41: Descartada | N41: =IF(Tabla5[[#This Row],[VALOR INVERSIÓN]]="","",IF(Tabla5[[#This Row],[VALOR INVERSIÓN]]<=10000000,100%*10%*22000,IF(AND(Tabla5[[#This Row],[VALOR INVERSIÓN]]>10000000,Tabla5[[#This Row],[VALOR INVERSIÓN]]<=20000000),60%*10%*22000,20%*10%*22000))) | O41: =IF(Tabla5[[#This Row],[ROI (MESES)]]="","",IF(Tabla5[[#This Row],[ROI (MESES)]]="N/A","0",IF(Tabla5[[#This Row],[ROI (MESES)]]="<=3",100%*10%*22000,IF(Tabla5[[#This Row],[ROI (MESES)]]=">3<=6",75%*10%*22000,25%*10%*22000)))) | P41: =IF(Tabla5[[#This Row],[FACILIDAD IMPLEM.]]="","",IF(Tabla5[[#This Row],[FACILIDAD IMPLEM.]]="A",100%*10%*22000,IF(AND(Tabla5[[#This Row],[FACILIDAD IMPLEM.]]="B"),50%*10%*22000,20%*10%*22000))) | Q41: =Tabla5[[#This Row],[IMPACTO AMBIENTAL (Máx. 25%)]]*70%*22000+Tabla5[[#This Row],[IMPACTO ECONÓMICO (Máx. 25%)]]*70%*22000+Tabla5[[#This Row],[IMPACTO SST (Máx. 20%)]]*70%*22000+Tabla5[[#This Row],[IMPACTO PRODUCTIVIDAD (Máx. 25%)]]*70%*22000+Tabla5[[#This Row],[IMPACTO ORDEN Y ASEO (Máx. 5%)]]*70%*22000 -> 0 | R41: =IFERROR(Tabla5[[#This Row],[PUNTOS VALOR INVERSIÓN]]+Tabla5[[#This Row],[PUNTOS ROI ]]+Tabla5[[#This Row],[PUNTOS FACILIDAD IMPLEM. ]]+Tabla5[[#This Row],[PUNTOS IMPACTO ]],"") | S41: 03/09/2024 Pendiente validar necesidad, utilidad y viabilidad con Supervisor materias primas y coordinador de PCC.
...

Sheet Puntos acumulados
A1: Nombre | B1: Cantidad Ideas | C1: Suma de Puntos | D1: Proceso
A2: Luis Carlos Ramos Rangel | B2: 10 | C2: 36498 | D2: =VLOOKUP(A2,'Tabla Calif. Puntos'!$B:$D,3,0) -> G.Técnica
A3: Paola Johana Restrepo Rios | B3: 7 | C3: 34870 | D3: =VLOOKUP(A3,'Tabla Calif. Puntos'!$B:$D,3,0) -> Comercial
A4: Sebastián Ossa Londoño | B4: 2 | C4: 23518 | D4: =VLOOKUP(A4,'Tabla Calif. Puntos'!$B:$D,3,0) -> Producción
A5: Jorge Andrés Carvajal | B5: 6 | C5: 21208 | D5: =VLOOKUP(A5,'Tabla Calif. Puntos'!$B:$D,3,0) -> Producción
A6: Jorge Eliecer Calderón Reyes | B6: 2 | C6: 16280 | D6: =VLOOKUP(A6,'Tabla Calif. Puntos'!$B:$D,3,0) -> G.Técnica
A7: Juan Camilo Agudelo Muñoz | B7: 2 | C7: 14190 | D7: =VLOOKUP(A7,'Tabla Calif. Puntos'!$B:$D,3,0) -> TI
A8: Roberto Carlos Rodríguez | B8: 3 | C8: 14124 | D8: =VLOOKUP(A8,'Tabla Calif. Puntos'!$B:$D,3,0) -> Producción
A9: Diego Uribe Castellanos | B9: 1 | C9: 13222 | D9: =VLOOKUP(A9,'Tabla Calif. Puntos'!$B:$D,3,0) -> G.Técnica
A10: Carlos Alberto Cardona Mira | B10: 3 | C10: 11704 | D10: =VLOOKUP(A10,'Tabla Calif. Puntos'!$B:$D,3,0) -> Comercial
A11: Jhon Jairo Villamizar Gutierrez | B11: 2 | C11: 10703 | D11: =VLOOKUP(A11,'Tabla Calif. Puntos'!$B:$D,3,0) -> Mantenimiento
A12: Alfredo Trujillo Cordoba | B12: 3 | C12: 9878 | D12: =VLOOKUP(A12,'Tabla Calif. Puntos'!$B:$D,3,0) -> G.Técnica
A13: Robert Smit Correa Conde | B13: 1 | C13: 9834 | D13: =VLOOKUP(A13,'Tabla Calif. Puntos'!$B:$D,3,0) -> Producción
... A56: Gustavo Adolfo Galeano Alvarez | B56: 1 | C56: 0 | D56: =VLOOKUP(A56,'Tabla Calif. Puntos'!$B:$D,3,0) -> Mantenimiento
A57: Juan Carlos Cano Ocampo | B57: 2 | C57: 0 | D57: G.Técnica
A58: Victoria Arciniegas Arteaga | B58: 2 | C58: 0 | D58: =VLOOKUP(A58,'Tabla Calif. Puntos'!$B:$D,3,0) -> G.Administrativa
A59: Fraiman Posada | B59: 1 | C59: 0 | D59: =VLOOKUP(A59,'Tabla Calif. Puntos'!$B:$D,3,0) -> Producción
A60: Jair José Aguilar Mora | B60: 1 | C60: 0 | D60: =VLOOKUP(A60,'Tabla Calif. Puntos'!$B:$D,3,0) -> Producción
A61: Hernan Dario Miranda Ramírez | B61: 3 | C61: 0 | D61: =VLOOKUP(A61,'Tabla Calif. Puntos'!$B:$D,3,0) -> Logística
A62: Jorge Andrés Aguilar | B62: 1 | C62: 0 | D62: =VLOOKUP(A62,'Tabla Calif. Puntos'!$B:$D,3,0) -> Producción
